<?xml version="1.0" ?>
<!-- =================================================================================== -->
<!-- |    This document was autogenerated by xacro from /home/j/afm_ws/install/afs_robot/share/afs_robot/urdf/afs_robot.urdf.xacro | -->
<!-- |    EDITING THIS FILE BY HAND IS NOT RECOMMENDED                                 | -->
<!-- =================================================================================== -->
<robot name="afs_robot">
  <!-- Позиция шарнира (0 = середина) -->
  <!-- Базовый линк (мир) -->
  <link name="base_link"/>
  <!-- Крепление передней рамы к базе -->
  <joint name="base_to_front" type="fixed">
    <parent link="base_link"/>
    <child link="front_frame"/>
    <origin rpy="0 0 0" xyz="1.0 0 0.1"/>
  </joint>
  <!-- Основные рамы -->
  <link name="front_frame">
    <visual>
      <geometry>
        <box size="1.0 0.8 0.2"/>
      </geometry>
      <material name="blue">
        <color rgba="0 0 0.8 1"/>
      </material>
    </visual>
  </link>
  <link name="rear_frame">
    <visual>
      <geometry>
        <box size="1.0 0.8 0.2"/>
      </geometry>
      <material name="red">
        <color rgba="0.8 0 0 1"/>
      </material>
    </visual>
  </link>
  <!-- Обновлённый шарнир сочленения -->
  <joint name="articulation_joint" type="revolute">
    <parent link="front_frame"/>
    <child link="rear_frame"/>
    <origin rpy="0 0 0" xyz="-0.8 0 0.1"/>
    <axis xyz="0 0 1"/>
    <limit effort="100" lower="-0.8" upper="0.8" velocity="1.0"/>
  </joint>
  <link name="front_left_wheel">
    <visual>
      <!-- Колесо лежит горизонтально -->
      <geometry>
        <cylinder length="0.15" radius="0.3"/>
      </geometry>
      <material name="black">
        <color rgba="0 0 0 1"/>
      </material>
      <origin rpy="1.5707963267948966 0 0" xyz="0 0 0"/>
      <!-- Поворот на 90° вокруг X -->
    </visual>
  </link>
  <joint name="front_left_drive_joint" type="continuous">
    <parent link="front_frame"/>
    <child link="front_left_wheel"/>
    <origin rpy="0 0 0" xyz="0.5 0.4 0"/>
    <axis xyz="0 1 0"/>
    <!-- Ось вращения горизонтальна -->
  </joint>
  <transmission name="front_left_drive_trans">
    <type>transmission_interface/SimpleTransmission</type>
    <joint name="front_left_drive_joint">
      <hardwareInterface>hardware_interface/VelocityJointInterface</hardwareInterface>
    </joint>
  </transmission>
  <link name="front_right_wheel">
    <visual>
      <!-- Колесо лежит горизонтально -->
      <geometry>
        <cylinder length="0.15" radius="0.3"/>
      </geometry>
      <material name="black">
        <color rgba="0 0 0 1"/>
      </material>
      <origin rpy="1.5707963267948966 0 0" xyz="0 0 0"/>
      <!-- Поворот на 90° вокруг X -->
    </visual>
  </link>
  <joint name="front_right_drive_joint" type="continuous">
    <parent link="front_frame"/>
    <child link="front_right_wheel"/>
    <origin rpy="0 0 0" xyz="0.5 -0.4 0"/>
    <axis xyz="0 1 0"/>
    <!-- Ось вращения горизонтальна -->
  </joint>
  <transmission name="front_right_drive_trans">
    <type>transmission_interface/SimpleTransmission</type>
    <joint name="front_right_drive_joint">
      <hardwareInterface>hardware_interface/VelocityJointInterface</hardwareInterface>
    </joint>
  </transmission>
  <link name="rear_left_wheel">
    <visual>
      <!-- Колесо лежит горизонтально -->
      <geometry>
        <cylinder length="0.15" radius="0.3"/>
      </geometry>
      <material name="black">
        <color rgba="0 0 0 1"/>
      </material>
      <origin rpy="1.5707963267948966 0 0" xyz="0 0 0"/>
      <!-- Поворот на 90° вокруг X -->
    </visual>
  </link>
  <joint name="rear_left_drive_joint" type="continuous">
    <parent link="rear_frame"/>
    <child link="rear_left_wheel"/>
    <origin rpy="0 0 0" xyz="-0.5 0.4 0"/>
    <axis xyz="0 1 0"/>
    <!-- Ось вращения горизонтальна -->
  </joint>
  <transmission name="rear_left_drive_trans">
    <type>transmission_interface/SimpleTransmission</type>
    <joint name="rear_left_drive_joint">
      <hardwareInterface>hardware_interface/VelocityJointInterface</hardwareInterface>
    </joint>
  </transmission>
  <link name="rear_right_wheel">
    <visual>
      <!-- Колесо лежит горизонтально -->
      <geometry>
        <cylinder length="0.15" radius="0.3"/>
      </geometry>
      <material name="black">
        <color rgba="0 0 0 1"/>
      </material>
      <origin rpy="1.5707963267948966 0 0" xyz="0 0 0"/>
      <!-- Поворот на 90° вокруг X -->
    </visual>
  </link>
  <joint name="rear_right_drive_joint" type="continuous">
    <parent link="rear_frame"/>
    <child link="rear_right_wheel"/>
    <origin rpy="0 0 0" xyz="-0.5 -0.4 0"/>
    <axis xyz="0 1 0"/>
    <!-- Ось вращения горизонтальна -->
  </joint>
  <transmission name="rear_right_drive_trans">
    <type>transmission_interface/SimpleTransmission</type>
    <joint name="rear_right_drive_joint">
      <hardwareInterface>hardware_interface/VelocityJointInterface</hardwareInterface>
    </joint>
  </transmission>
  <!-- ros2_control -->
  <ros2_control name="afs_control" type="system">
    <hardware>
      <plugin>fake_components/FakeSystem</plugin>
    </hardware>
    <!-- Шарнир сочленения -->
    <joint name="articulation_joint">
      <command_interface name="position"/>
      <state_interface name="position"/>
    </joint>
    <!-- Приводные шарниры -->
    <joint name="front_left_drive_joint">
      <command_interface name="velocity"/>
      <state_interface name="velocity"/>
    </joint>
    <joint name="front_right_drive_joint">
      <command_interface name="velocity"/>
      <state_interface name="velocity"/>
    </joint>
    <joint name="rear_left_drive_joint">
      <command_interface name="velocity"/>
      <state_interface name="velocity"/>
    </joint>
    <joint name="rear_right_drive_joint">
      <command_interface name="velocity"/>
      <state_interface name="velocity"/>
    </joint>
  </ros2_control>
</robot>
